Workbook

Sheet RElist
A1: Restriction enzymes the RE sheet looks up. From row 4 down, one enzyme per row: Enzyme, Buffer, Reaction temp., Heat inactivation (No if it cannot be heat-inactivated).
A2: Names are matched as written in the design record, ignoring case, without registered-trademark signs or spaces at the ends. Add rows below the last one; the RE sheet reads A4:D650. Check every value against the current datasheet.
A3: Enzyme | B3: Buffer | C3: Reaction temp. | D3: Heat inactivation

Sheet Data
A1: Plasmid Construction | B1: Project No. | C1: Sub. No. | D1: Method | E1: Plasmid map | F1: Length | G1: Plasmid name | H1: RE1 | I1: RE2 | J1: Backbone plasmid/gDNA | K1: Backbone prep. | L1: Length (bp) | M1: PCR primer/Oligo 1 | N1: PCR primer/Oligo 2 | O1: Template | P1: Length (bp) | Q1: PCR/Annealing | R1: DpnI | S1: Transformation | T1: Miniprep | U1: Plasmid Ext. | V1: Nanopore | W1: Sequence check | X1: Plasmid No. | Y1: Plasmid name | Z1: Competent cell | AA1: Conc | AB1: Design | AC1: Order | AD1: Obtained | AE1: Made by | AF1: Entered by | AG1: Project number

Sheet RE
A1: =TODAY() | C1: Cloning with HiFi assembly
A3: 1. Restriction digestion of the backbone
A4: □ | B4: Thaw the backbone plasmid and 10×CutSmart at room temperature
B6: Samples to digest | C6: =COUNTIF($F$14:$F$25,"RE") | D6: samples
B7: Samples prepared by PCR | C7: =COUNTIF($F$14:$F$25,"PCR") | D7: samples
B8: Total volume per reaction | C8: 50 | D8: uL
B9: Plasmid DNA | C9: 10 | D9: uL/sample
B10: Column purification | C10: Yes | E10: No heat inactivation is needed when this is Yes
B12: • Reaction mix per sample
B13: Sub. No. | C13: Backbone | D13: RE1 | E13: RE2 | F13: Prep | G13: Plasmid DNA | H13: 10×CutSmart | I13: RE1 (uL) | J13: RE2 (uL) | K13: H2O | L13: Total | M13: Reaction temp. | N13: Heat inactivation
A14: =IF($F14="RE","□","") | B14: =IF(Data!C2="","",Data!C2) | C14: =IF(Data!C2="","",Data!J2) | D14: =IF(Data!C2="","",Data!H2) | E14: =IF(Data!C2="","",IF(Data!I2="","",Data!I2)) | F14: =IF(OR(Data!C2="",Data!H2=""),"",IF(ISNA(MATCH(Data!H2,RElist!$A$4:$A$650,0)),"PCR","RE")) | G14: =IF($F14<>"RE","",$C$9) | H14: =IF($F14<>"RE","",$C$8/10) | I14: =IF($F14<>"RE","",IF(D14="",0,$C$8/25)) | J14: =IF($F14<>"RE","",IF(E14="",0,$C$8/25)) | K14: =IF($F14<>"RE","",$C$8-G14-H14-I14-J14) | L14: =IF($F14<>"RE","",SUM(G14:K14)) | M14: =IF($F14<>"RE","",IFERROR(IF(E14="",VLOOKUP(D14,RElist!$A$4:$D$650,3,FALSE),IF(VLOOKUP(D14,RElist!$A$4:$D$650,3,FALSE)=VLOOKUP(E14,RElist!$A$4:$D$650,3,FALSE),VLOOKUP(D14,RElist!$A$4:$D$650,3,FALSE),"Check conditions")),"Check")) | N14: =IF($F14<>"RE","",IF($C$10="Yes","Not needed",IFERROR(IF(IF(E14="",VLOOKUP(D14,RElist!$A$4:$D$650,4,FALSE)="No",OR(VLOOKUP(D14,RElist!$A$4:$D$650,4,FALSE)="No",VLOOKUP(E14,RElist!$A$4:$D$650,4,FALSE)="No")),"Not possible","Possible"),"Check")))
A15: =IF($F15="RE","□","") | B15: =IF(Data!C3="","",Data!C3) | C15: =IF(Data!C3="","",Data!J3) | D15: =IF(Data!C3="","",Data!H3) | E15: =IF(Data!C3="","",IF(Data!I3="","",Data!I3)) | F15: =IF(OR(Data!C3="",Data!H3=""),"",IF(ISNA(MATCH(Data!H3,RElist!$A$4:$A$650,0)),"PCR","RE")) | G15: =IF($F15<>"RE","",$C$9) | H15: =IF($F15<>"RE","",$C$8/10) | I15: =IF($F15<>"RE","",IF(D15="",0,$C$8/25)) | J15: =IF($F15<>"RE","",IF(E15="",0,$C$8/25)) | K15: =IF($F15<>"RE","",$C$8-G15-H15-I15-J15) | L15: =IF($F15<>"RE","",SUM(G15:K15)) | M15: =IF($F15<>"RE","",IFERROR(IF(E15="",VLOOKUP(D15,RElist!$A$4:$D$650,3,FALSE),IF(VLOOKUP(D15,RElist!$A$4:$D$650,3,FALSE)=VLOOKUP(E15,RElist!$A$4:$D$650,3,FALSE),VLOOKUP(D15,RElist!$A$4:$D$650,3,FALSE),"Check conditions")),"Check")) | N15: =IF($F15<>"RE","",IF($C$10="Yes","Not needed",IFERROR(IF(IF(E15="",VLOOKUP(D15,RElist!$A$4:$D$650,4,FALSE)="No",OR(VLOOKUP(D15,RElist!$A$4:$D$650,4,FALSE)="No",VLOOKUP(E15,RElist!$A$4:$D$650,4,FALSE)="No")),"Not possible","Possible"),"Check")))
A16: =IF($F16="RE","□","") | B16: =IF(Data!C4="","",Data!C4) | C16: =IF(Data!C4="","",Data!J4) | D16: =IF(Data!C4="","",Data!H4) | E16: =IF(Data!C4="","",IF(Data!I4="","",Data!I4)) | F16: =IF(OR(Data!C4="",Data!H4=""),"",IF(ISNA(MATCH(Data!H4,RElist!$A$4:$A$650,0)),"PCR","RE")) | G16: =IF($F16<>"RE","",$C$9) | H16: =IF($F16<>"RE","",$C$8/10) | I16: =IF($F16<>"RE","",IF(D16="",0,$C$8/25)) | J16: =IF($F16<>"RE","",IF(E16="",0,$C$8/25)) | K16: =IF($F16<>"RE","",$C$8-G16-H16-I16-J16) | L16: =IF($F16<>"RE","",SUM(G16:K16)) | M16: =IF($F16<>"RE","",IFERROR(IF(E16="",VLOOKUP(D16,RElist!$A$4:$D$650,3,FALSE),IF(VLOOKUP(D16,RElist!$A$4:$D$650,3,FALSE)=VLOOKUP(E16,RElist!$A$4:$D$650,3,FALSE),VLOOKUP(D16,RElist!$A$4:$D$650,3,FALSE),"Check conditions")),"Check")) | N16: =IF($F16<>"RE","",IF($C$10="Yes","Not needed",IFERROR(IF(IF(E16="",VLOOKUP(D16,RElist!$A$4:$D$650,4,FALSE)="No",OR(VLOOKUP(D16,RElist!$A$4:$D$650,4,FALSE)="No",VLOOKUP(E16,RElist!$A$4:$D$650,4,FALSE)="No")),"Not possible","Possible"),"Check")))
A17: =IF($F17="RE","□","") | B17: =IF(Data!C5="","",Data!C5) | C17: =IF(Data!C5="","",Data!J5) | D17: =IF(Data!C5="","",Data!H5) | E17: =IF(Data!C5="","",IF(Data!I5="","",Data!I5)) | F17: =IF(OR(Data!C5="",Data!H5=""),"",IF(ISNA(MATCH(Data!H5,RElist!$A$4:$A$650,0)),"PCR","RE")) | G17: =IF($F17<>"RE","",$C$9) | H17: =IF($F17<>"RE","",$C$8/10) | I17: =IF($F17<>"RE","",IF(D17="",0,$C$8/25)) | J17: =IF($F17<>"RE","",IF(E17="",0,$C$8/25)) | K17: =IF($F17<>"RE","",$C$8-G17-H17-I17-J17) | L17: =IF($F17<>"RE","",SUM(G17:K17)) | M17: =IF($F17<>"RE","",IFERROR(IF(E17="",VLOOKUP(D17,RElist!$A$4:$D$650,3,FALSE),IF(VLOOKUP(D17,RElist!$A$4:$D$650,3,FALSE)=VLOOKUP(E17,RElist!$A$4:$D$650,3,FALSE),VLOOKUP(D17,RElist!$A$4:$D$650,3,FALSE),"Check conditions")),"Check")) | N17: =IF($F17<>"RE","",IF($C$10="Yes","Not needed",IFERROR(IF(IF(E17="",VLOOKUP(D17,RElist!$A$4:$D$650,4,FALSE)="No",OR(VLOOKUP(D17,RElist!$A$4:$D$650,4,FALSE)="No",VLOOKUP(E17,RElist!$A$4:$D$650,4,FALSE)="No")),"Not possible","Possible"),"Check")))
A18: =IF($F18="RE","□","") | B18: =IF(Data!C6="","",Data!C6) | C18: =IF(Data!C6="","",Data!J6) | D18: =IF(Data!C6="","",Data!H6) | E18: =IF(Data!C6="","",IF(Data!I6="","",Data!I6)) | F18: =IF(OR(Data!C6="",Data!H6=""),"",IF(ISNA(MATCH(Data!H6,RElist!$A$4:$A$650,0)),"PCR","RE")) | G18: =IF($F18<>"RE","",$C$9) | H18: =IF($F18<>"RE","",$C$8/10) | I18: =IF($F18<>"RE","",IF(D18="",0,$C$8/25)) | J18: =IF($F18<>"RE","",IF(E18="",0,$C$8/25)) | K18: =IF($F18<>"RE","",$C$8-G18-H18-I18-J18) | L18: =IF($F18<>"RE","",SUM(G18:K18)) | M18: =IF($F18<>"RE","",IFERROR(IF(E18="",VLOOKUP(D18,RElist!$A$4:$D$650,3,FALSE),IF(VLOOKUP(D18,RElist!$A$4:$D$650,3,FALSE)=VLOOKUP(E18,RElist!$A$4:$D$650,3,FALSE),VLOOKUP(D18,RElist!$A$4:$D$650,3,FALSE),"Check conditions")),"Check")) | N18: =IF($F18<>"RE","",IF($C$10="Yes","Not needed",IFERROR(IF(IF(E18="",VLOOKUP(D18,RElist!$A$4:$D$650,4,FALSE)="No",OR(VLOOKUP(D18,RElist!$A$4:$D$650,4,FALSE)="No",VLOOKUP(E18,RElist!$A$4:$D$650,4,FALSE)="No")),"Not possible","Possible"),"Check")))
A19: =IF($F19="RE","□","") | B19: =IF(Data!C7="","",Data!C7) | C19: =IF(Data!C7="","",Data!J7) | D19: =IF(Data!C7="","",Data!H7) | E19: =IF(Data!C7="","",IF(Data!I7="","",Data!I7)) | F19: =IF(OR(Data!C7="",Data!H7=""),"",IF(ISNA(MATCH(Data!H7,RElist!$A$4:$A$650,0)),"PCR","RE")) | G19: =IF($F19<>"RE","",$C$9) | H19: =IF($F19<>"RE","",$C$8/10) | I19: =IF($F19<>"RE","",IF(D19="",0,$C$8/25)) | J19: =IF($F19<>"RE","",IF(E19="",0,$C$8/25)) | K19: =IF($F19<>"RE","",$C$8-G19-H19-I19-J19) | L19: =IF($F19<>"RE","",SUM(G19:K19)) | M19: =IF($F19<>"RE","",IFERROR(IF(E19="",VLOOKUP(D19,RElist!$A$4:$D$650,3,FALSE),IF(VLOOKUP(D19,RElist!$A$4:$D$650,3,FALSE)=VLOOKUP(E19,RElist!$A$4:$D$650,3,FALSE),VLOOKUP(D19,RElist!$A$4:$D$650,3,FALSE),"Check conditions")),"Check")) | N19: =IF($F19<>"RE","",IF($C$10="Yes","Not needed",IFERROR(IF(IF(E19="",VLOOKUP(D19,RElist!$A$4:$D$650,4,FALSE)="No",OR(VLOOKUP(D19,RElist!$A$4:$D$650,4,FALSE)="No",VLOOKUP(E19,RElist!$A$4:$D$650,4,FALSE)="No")),"Not possible","Possible"),"Check")))
A20: =IF($F20="RE","□","") | B20: =IF(Data!C8="","",Data!C8) | C20: =IF(Data!C8="","",Data!J8) | D20: =IF(Data!C8="","",Data!H8) | E20: =IF(Data!C8="","",IF(Data!I8="","",Data!I8)) | F20: =IF(OR(Data!C8="",Data!H8=""),"",IF(ISNA(MATCH(Data!H8,RElist!$A$4:$A$650,0)),"PCR","RE")) | G20: =IF($F20<>"RE","",$C$9) | H20: =IF($F20<>"RE","",$C$8/10) | I20: =IF($F20<>"RE","",IF(D20="",0,$C$8/25)) | J20: =IF($F20<>"RE","",IF(E20="",0,$C$8/25)) | K20: =IF($F20<>"RE","",$C$8-G20-H20-I20-J20) | L20: =IF($F20<>"RE","",SUM(G20:K20)) | M20: =IF($F20<>"RE","",IFERROR(IF(E20="",VLOOKUP(D20,RElist!$A$4:$D$650,3,FALSE),IF(VLOOKUP(D20,RElist!$A$4:$D$650,3,FALSE)=VLOOKUP(E20,RElist!$A$4:$D$650,3,FALSE),VLOOKUP(D20,RElist!$A$4:$D$650,3,FALSE),"Check conditions")),"Check")) | N20: =IF($F20<>"RE","",IF($C$10="Yes","Not needed",IFERROR(IF(IF(E20="",VLOOKUP(D20,RElist!$A$4:$D$650,4,FALSE)="No",OR(VLOOKUP(D20,RElist!$A$4:$D$650,4,FALSE)="No",VLOOKUP(E20,RElist!$A$4:$D$650,4,FALSE)="No")),"Not possible","Possible"),"Check")))
A21: =IF($F21="RE","□","") | B21: =IF(Data!C9="","",Data!C9) | C21: =IF(Data!C9="","",Data!J9) | D21: =IF(Data!C9="","",Data!H9) | E21: =IF(Data!C9="","",IF(Data!I9="","",Data!I9)) | F21: =IF(OR(Data!C9="",Data!H9=""),"",IF(ISNA(MATCH(Data!H9,RElist!$A$4:$A$650,0)),"PCR","RE")) | G21: =IF($F21<>"RE","",$C$9) | H21: =IF($F21<>"RE","",$C$8/10) | I21: =IF($F21<>"RE","",IF(D21="",0,$C$8/25)) | J21: =IF($F21<>"RE","",IF(E21="",0,$C$8/25)) | K21: =IF($F21<>"RE","",$C$8-G21-H21-I21-J21) | L21: =IF($F21<>"RE","",SUM(G21:K21)) | M21: =IF($F21<>"RE","",IFERROR(IF(E21="",VLOOKUP(D21,RElist!$A$4:$D$650,3,FALSE),IF(VLOOKUP(D21,RElist!$A$4:$D$650,3,FALSE)=VLOOKUP(E21,RElist!$A$4:$D$650,3,FALSE),VLOOKUP(D21,RElist!$A$4:$D$650,3,FALSE),"Check conditions")),"Check")) | N21: =IF($F21<>"RE","",IF($C$10="Yes","Not needed",IFERROR(IF(IF(E21="",VLOOKUP(D21,RElist!$A$4:$D$650,4,FALSE)="No",OR(VLOOKUP(D21,RElist!$A$4:$D$650,4,FALSE)="No",VLOOKUP(E21,RElist!$A$4:$D$650,4,FALSE)="No")),"Not possible","Possible"),"Check")))
A22: =IF($F22="RE","□","") | B22: =IF(Data!C10="","",Data!C10) | C22: =IF(Data!C10="","",Data!J10) | D22: =IF(Data!C10="","",Data!H10) | E22: =IF(Data!C10="","",IF(Data!I10="","",Data!I10)) | F22: =IF(OR(Data!C10="",Data!H10=""),"",IF(ISNA(MATCH(Data!H10,RElist!$A$4:$A$650,0)),"PCR","RE")) | G22: =IF($F22<>"RE","",$C$9) | H22: =IF($F22<>"RE","",$C$8/10) | I22: =IF($F22<>"RE","",IF(D22="",0,$C$8/25)) | J22: =IF($F22<>"RE","",IF(E22="",0,$C$8/25)) | K22: =IF($F22<>"RE","",$C$8-G22-H22-I22-J22) | L22: =IF($F22<>"RE","",SUM(G22:K22)) | M22: =IF($F22<>"RE","",IFERROR(IF(E22="",VLOOKUP(D22,RElist!$A$4:$D$650,3,FALSE),IF(VLOOKUP(D22,RElist!$A$4:$D$650,3,FALSE)=VLOOKUP(E22,RElist!$A$4:$D$650,3,FALSE),VLOOKUP(D22,RElist!$A$4:$D$650,3,FALSE),"Check conditions")),"Check")) | N22: =IF($F22<>"RE","",IF($C$10="Yes","Not needed",IFERROR(IF(IF(E22="",VLOOKUP(D22,RElist!$A$4:$D$650,4,FALSE)="No",OR(VLOOKUP(D22,RElist!$A$4:$D$650,4,FALSE)="No",VLOOKUP(E22,RElist!$A$4:$D$650,4,FALSE)="No")),"Not possible","Possible"),"Check")))
A23: =IF($F23="RE","□","") | B23: =IF(Data!C11="","",Data!C11) | C23: =IF(Data!C11="","",Data!J11) | D23: =IF(Data!C11="","",Data!H11) | E23: =IF(Data!C11="","",IF(Data!I11="","",Data!I11)) | F23: =IF(OR(Data!C11="",Data!H11=""),"",IF(ISNA(MATCH(Data!H11,RElist!$A$4:$A$650,0)),"PCR","RE")) | G23: =IF($F23<>"RE","",$C$9) | H23: =IF($F23<>"RE","",$C$8/10) | I23: =IF($F23<>"RE","",IF(D23="",0,$C$8/25)) | J23: =IF($F23<>"RE","",IF(E23="",0,$C$8/25)) | K23: =IF($F23<>"RE","",$C$8-G23-H23-I23-J23) | L23: =IF($F23<>"RE","",SUM(G23:K23)) | M23: =IF($F23<>"RE","",IFERROR(IF(E23="",VLOOKUP(D23,RElist!$A$4:$D$650,3,FALSE),IF(VLOOKUP(D23,RElist!$A$4:$D$650,3,FALSE)=VLOOKUP(E23,RElist!$A$4:$D$650,3,FALSE),VLOOKUP(D23,RElist!$A$4:$D$650,3,FALSE),"Check conditions")),"Check")) | N23: =IF($F23<>"RE","",IF($C$10="Yes","Not needed",IFERROR(IF(IF(E23="",VLOOKUP(D23,RElist!$A$4:$D$650,4,FALSE)="No",OR(VLOOKUP(D23,RElist!$A$4:$D$650,4,FALSE)="No",VLOOKUP(E23,RElist!$A$4:$D$650,4,FALSE)="No")),"Not possible","Possible"),"Check")))
A24: =IF($F24="RE","□","") | B24: =IF(Data!C12="","",Data!C12) | C24: =IF(Data!C12="","",Data!J12) | D24: =IF(Data!C12="","",Data!H12) | E24: =IF(Data!C12="","",IF(Data!I12="","",Data!I12)) | F24: =IF(OR(Data!C12="",Data!H12=""),"",IF(ISNA(MATCH(Data!H12,RElist!$A$4:$A$650,0)),"PCR","RE")) | G24: =IF($F24<>"RE","",$C$9) | H24: =IF($F24<>"RE","",$C$8/10) | I24: =IF($F24<>"RE","",IF(D24="",0,$C$8/25)) | J24: =IF($F24<>"RE","",IF(E24="",0,$C$8/25)) | K24: =IF($F24<>"RE","",$C$8-G24-H24-I24-J24) | L24: =IF($F24<>"RE","",SUM(G24:K24)) | M24: =IF($F24<>"RE","",IFERROR(IF(E24="",VLOOKUP(D24,RElist!$A$4:$D$650,3,FALSE),IF(VLOOKUP(D24,RElist!$A$4:$D$650,3,FALSE)=VLOOKUP(E24,RElist!$A$4:$D$650,3,FALSE),VLOOKUP(D24,RElist!$A$4:$D$650,3,FALSE),"Check conditions")),"Check")) | N24: =IF($F24<>"RE","",IF($C$10="Yes","Not needed",IFERROR(IF(IF(E24="",VLOOKUP(D24,RElist!$A$4:$D$650,4,FALSE)="No",OR(VLOOKUP(D24,RElist!$A$4:$D$650,4,FALSE)="No",VLOOKUP(E24,RElist!$A$4:$D$650,4,FALSE)="No")),"Not possible","Possible"),"Check")))
A25: =IF($F25="RE","□","") | B25: =IF(Data!C13="","",Data!C13) | C25: =IF(Data!C13="","",Data!J13) | D25: =IF(Data!C13="","",Data!H13) | E25: =IF(Data!C13="","",IF(Data!I13="","",Data!I13)) | F25: =IF(OR(Data!C13="",Data!H13=""),"",IF(ISNA(MATCH(Data!H13,RElist!$A$4:$A$650,0)),"PCR","RE")) | G25: =IF($F25<>"RE","",$C$9) | H25: =IF($F25<>"RE","",$C$8/10) | I25: =IF($F25<>"RE","",IF(D25="",0,$C$8/25)) | J25: =IF($F25<>"RE","",IF(E25="",0,$C$8/25)) | K25: =IF($F25<>"RE","",$C$8-G25-H25-I25-J25) | L25: =IF($F25<>"RE","",SUM(G25:K25)) | M25: =IF($F25<>"RE","",IFERROR(IF(E25="",VLOOKUP(D25,RElist!$A$4:$D$650,3,FALSE),IF(VLOOKUP(D25,RElist!$A$4:$D$650,3,FALSE)=VLOOKUP(E25,RElist!$A$4:$D$650,3,FALSE),VLOOKUP(D25,RElist!$A$4:$D$650,3,FALSE),"Check conditions")),"Check")) | N25: =IF($F25<>"RE","",IF($C$10="Yes","Not needed",IFERROR(IF(IF(E25="",VLOOKUP(D25,RElist!$A$4:$D$650,4,FALSE)="No",OR(VLOOKUP(D25,RElist!$A$4:$D$650,4,FALSE)="No",VLOOKUP(E25,RElist!$A$4:$D$650,4,FALSE)="No")),"Not possible","Possible"),"Check")))
B27: • Premix of H2O + 10×CutSmart
D28: Mix tubes | E28: =IF($C$6=0,0,$C$6+2) | F28: tubes (samples + 2)
B29: Reagent | C29: Final | D29: 1 sample (uL) | E29: Mix (uL) | F29: Notes
A30: □ | B30: milliQ | D30: =IFERROR(INDEX($K$14:$K$25,MATCH("RE",$F$14:$F$25,0)),0) | E30: =D30*$E$28
A31: □ | B31: 10×CutSmart | C31: 1x | D31: =$C$8/10 | E31: =D31*$E$28
B32: Master mix subtotal | D32: =SUM(D30:D31) | E32: =SUM(E30:E31)
A33: □ | B33: Backbone plasmid | D33: =$C$9 | F33: Add to each tube individually
A34: □ | B34: Restriction enzyme (per tube) | D34: =$C$8/25 | F34: Add to each tube individually
B35: Total | D35: =IF($C$6=0,0,$C$8) | F35: uL
B36: =IF($C$6=0,"",IF(COUNTIFS($F$14:$F$25,"RE",$K$14:$K$25,D30)=$C$6,"","Note: the H2O volume differs between samples (a different number of enzymes). Split the mix."))
A38: □ | B38: Mix well by vortexing, then spin down
A39: □ | B39: React under the following conditions | C39: =IFERROR(INDEX($M$14:$M$25,MATCH("RE",$F$14:$F$25,0)),"") | D39: 60 min
A40: □ | B40: =IF($C$10="Yes","Purify on a column (no heat inactivation needed)","Heat-inactivate")
B41: (checkpoint) Can be stored at -30°C

Sheet PCR
A1: =TODAY() | C1: Cloning with HiFi assembly
A3: 2. PCR of the insert
A4: □ | B4: Thaw KOD One, the primers and the templates at room temperature
B6: PCR tubes | C6: =COUNTIF($A$55:$A$66,"□") | D6: tubes
B7: Mix tubes to prepare | C7: =IF($C$6=0,0,$C$6+2) | D7: tubes | E7: (PCR tubes + 2)
B8: Longest product | C8: =IF($C$6=0,0,MAX($G$55:$G$66)) | D8: bp
B9: Extension time | C9: =IF($C$8=0,"",MAX(5,ROUNDUP($C$8/1000*5,0))) | D9: sec | E9: KOD One 5 sec/kb, set by the longest product
B10: =IF(COUNTIFS($A$55:$A$66,"□",$G$55:$G$66,"")=0,"","Note: some rows have an empty Length (bp). The extension time is calculated from the filled rows only.")
B12: • Template solution (1/5 dilution, per template)
B13: Reagent | C13: Final | D13: Volume (uL)
A14: □ | B14: Template DNA | D14: 2
A15: □ | B15: H2O | D15: 8
B16: Total | D16: =SUM(D14:D15) | E16: uL
B18: • Primer solution (100 uM → 10 uM, per primer)
B19: Reagent | C19: Final | D19: Volume (uL)
A20: □ | B20: 100 uM Primer | C20: 10 uM | D20: 2
A21: □ | B21: H2O | D21: 18
B22: Total | D22: =SUM(D20:D21) | E22: uL
B24: • PCR mix preparation
D25: Mix tubes | E25: =$C$7 | F25: tubes
B26: Reagent | C26: Final | D26: 1 sample (uL) | E26: Mix (uL) | F26: Notes
A27: □ | B27: H2O | D27: 21 | E27: =D27*$E$25
A28: □ | B28: KOD One | C28: 1x | D28: 25 | E28: =D28*$E$25
B29: Master mix subtotal | D29: =SUM(D27:D28) | E29: =SUM(E27:E28)
A30: □ | B30: 10 uM Primer 5' | D30: 1.5 | F30: Add to each tube individually
A31: □ | B31: 10 uM Primer 3' | D31: 1.5 | F31: Add to each tube individually
A32: □ | B32: 1/5 Template DNA | D32: 1 | F32: Add to each tube individually
B33: Total | D33: =D29+SUM(D30:D32) | F33: uL
B35: • PCR conditions (KOD One)
B36: Step | C36: Temp. | D36: Time | E36: Cycles
A37: □ | B37: Denature | C37: 98°C | D37: 2 min
B38: Denature | C38: 98°C | D38: 10 sec | E38: 40
B39: Annealing | C39: 55°C | D39: 5 sec
B40: Extension | C40: 68°C | D40: =IF($C$9="","",$C$9&" sec")
B41: Hold | C41: 4°C | D41: ∞
B43: • DpnI digestion
D44: Mix tubes | E44: =$C$7 | F44: tubes
B45: Reagent | C45: Final | D45: 1 sample (uL) | E45: Mix (uL) | F45: Notes
A46: □ | B46: 10×FD | D46: 5.5 | E46: =D46*$E$44
A47: □ | B47: DpnI | D47: 1 | E47: =D47*$E$44
...

Sheet HiFi
A1: =TODAY() | B1: Insert : backbone ratio = 2 : 1
A2: Total | C2: Insert reaction conc. | E2: Backbone reaction conc. | G2: =IF(A8>3,"Total conc.: "&0.02*A3&"~"&0.05*A3&" pmol","Total conc.: "&0.003*A3&"~"&0.02*A3&" pmol")
A3: 5 | B3: uL | C3: =0.007*A3 | D3: pmol | E3: =IF(A8>3,C3,C3/2) | F3: pmol | G3: =C3*A8+E3 | H3: pmol
B6: Insert fragments
A7: Inserts | B7: DNA sample (Primer No.) | C7: Conc. | D7: Fragment length (bp) | E7: Fragment stock conc. | G7: Reaction conc. | H7: Volume needed (final 20 uL) | I7: Volume needed (final 10 uL) | J7: Dilution factor
A8: =MAX(1,COUNTIF(L9:L20,MAX(1,IFERROR(MODE(L9:L20),1)))) | C8: ng/uL | E8: nmol/L | F8: pmol/uL | G8: pmol/uL | H8: uL | I8: uL
A9: =IF(AND(Data!B2<>"",Data!C2=""),A8,Data!C2) | B9: =Data!M2&"/"&Data!N2 | D9: =Data!P2 | E9: =F9*1000 | F9: =C9*1000/D9/650 | G9: =$C$3 | H9: =G9/F9 | I9: =H9/2 | J9: 1 | L9: =IF(A9>0,A9,ROW(A9)-ROW($A$8)) | M9: =C9>0
A10: =IF(AND(Data!B3<>"",Data!C3=""),A9,Data!C3) | B10: =Data!M3&"/"&Data!N3 | D10: =Data!P3 | E10: =F10*1000 | F10: =C10*1000/D10/650 | G10: =$C$3 | H10: =G10/F10 | I10: =H10/2 | J10: 1 | L10: =IF(A10>0,A10,ROW(A10)-ROW($A$8)) | M10: =C10>0
A11: =IF(AND(Data!B4<>"",Data!C4=""),A10,Data!C4) | B11: =Data!M4&"/"&Data!N4 | D11: =Data!P4 | E11: =F11*1000 | F11: =C11*1000/D11/650 | G11: =$C$3 | H11: =G11/F11 | I11: =H11/2 | J11: 1 | L11: =IF(A11>0,A11,ROW(A11)-ROW($A$8)) | M11: =C11>0
A12: =IF(AND(Data!B5<>"",Data!C5=""),A11,Data!C5) | B12: =Data!M5&"/"&Data!N5 | D12: =Data!P5 | E12: =F12*1000 | F12: =C12*1000/D12/650 | G12: =$C$3 | H12: =G12/F12 | I12: =H12/2 | J12: 1 | L12: =IF(A12>0,A12,ROW(A12)-ROW($A$8)) | M12: =C12>0
A13: =IF(AND(Data!B6<>"",Data!C6=""),A12,Data!C6) | B13: =Data!M6&"/"&Data!N6 | D13: =Data!P6 | E13: =F13*1000 | F13: =C13*1000/D13/650 | G13: =$C$3 | H13: =G13/F13 | I13: =H13/2 | J13: 1 | L13: =IF(A13>0,A13,ROW(A13)-ROW($A$8)) | M13: =C13>0
A14: =IF(AND(Data!B7<>"",Data!C7=""),A13,Data!C7) | B14: =Data!M7&"/"&Data!N7 | D14: =Data!P7 | E14: =F14*1000 | F14: =C14*1000/D14/650 | G14: =$C$3 | H14: =G14/F14 | I14: =H14/2 | J14: 1 | L14: =IF(A14>0,A14,ROW(A14)-ROW($A$8)) | M14: =C14>0
A15: =IF(AND(Data!B8<>"",Data!C8=""),A14,Data!C8) | B15: =Data!M8&"/"&Data!N8 | D15: =Data!P8 | E15: =F15*1000 | F15: =C15*1000/D15/650 | G15: =$C$3 | H15: =G15/F15 | I15: =H15/2 | J15: 1 | L15: =IF(A15>0,A15,ROW(A15)-ROW($A$8)) | M15: =C15>0
A16: =IF(AND(Data!B9<>"",Data!C9=""),A15,Data!C9) | B16: =Data!M9&"/"&Data!N9 | D16: =Data!P9 | E16: =F16*1000 | F16: =C16*1000/D16/650 | G16: =$C$3 | H16: =G16/F16 | I16: =H16/2 | J16: 1 | L16: =IF(A16>0,A16,ROW(A16)-ROW($A$8)) | M16: =C16>0
A17: =IF(AND(Data!B10<>"",Data!C10=""),A16,Data!C10) | B17: =Data!M10&"/"&Data!N10 | D17: =Data!P10 | E17: =F17*1000 | F17: =C17*1000/D17/650 | G17: =$C$3 | H17: =G17/F17 | I17: =H17/2 | J17: 1 | L17: =IF(A17>0,A17,ROW(A17)-ROW($A$8)) | M17: =C17>0
A18: =IF(AND(Data!B11<>"",Data!C11=""),A17,Data!C11) | B18: =Data!M11&"/"&Data!N11 | D18: =Data!P11 | E18: =F18*1000 | F18: =C18*1000/D18/650 | G18: =$C$3 | H18: =G18/F18 | I18: =H18/2 | J18: 1 | L18: =IF(A18>0,A18,ROW(A18)-ROW($A$8)) | M18: =C18>0
A19: =IF(AND(Data!B12<>"",Data!C12=""),A18,Data!C12) | B19: =Data!M12&"/"&Data!N12 | D19: =Data!P12 | E19: =F19*1000 | F19: =C19*1000/D19/650 | G19: =$C$3 | H19: =G19/F19 | I19: =H19/2 | J19: 1 | L19: =IF(A19>0,A19,ROW(A19)-ROW($A$8)) | M19: =C19>0
A20: =IF(AND(Data!B13<>"",Data!C13=""),A19,Data!C13) | B20: =Data!M13&"/"&Data!N13 | D20: =Data!P13 | E20: =F20*1000 | F20: =C20*1000/D20/650 | G20: =$C$3 | H20: =G20/F20 | I20: =H20/2 | J20: 1 | L20: =IF(A20>0,A20,ROW(A20)-ROW($A$8)) | M20: =C20>0
B22: Backbone fragments
B23: Sample name (Backbone name) | C23: Conc. | D23: Fragment length (bp) | E23: Fragment stock conc. | G23: Reaction conc. | H23: Volume needed (final 20 uL) | I23: Volume needed (final 10 uL) | J23: Dilution factor
C24: ng/uL | E24: nmol/L | F24: pmol/uL | G24: pmol/uL | H24: uL | I24: uL
A25: =Data!C2 | B25: =Data!J2 | D25: =Data!L2 | E25: =F25*1000 | F25: =C25*1000/D25/650 | G25: =$C$3 | H25: =G25/F25 | I25: =H25/2 | J25: 1
A26: =Data!C3 | B26: =Data!J3 | D26: =Data!L3 | E26: =F26*1000 | F26: =C26*1000/D26/650 | G26: =$C$3 | H26: =G26/F26 | I26: =H26/2 | J26: 1
A27: =Data!C4 | B27: =Data!J4 | D27: =Data!L4 | E27: =F27*1000 | F27: =C27*1000/D27/650 | G27: =$C$3 | H27: =G27/F27 | I27: =H27/2 | J27: 1
A28: =Data!C5 | B28: =Data!J5 | D28: =Data!L5 | E28: =F28*1000 | F28: =C28*1000/D28/650 | G28: =$C$3 | H28: =G28/F28 | I28: =H28/2 | J28: 1
A29: =Data!C6 | B29: =Data!J6 | D29: =Data!L6 | E29: =F29*1000 | F29: =C29*1000/D29/650 | G29: =$C$3 | H29: =G29/F29 | I29: =H29/2 | J29: 1
A30: =Data!C7 | B30: =Data!J7 | D30: =Data!L7 | E30: =F30*1000 | F30: =C30*1000/D30/650 | G30: =$C$3 | H30: =G30/F30 | I30: =H30/2 | J30: 1
A31: =Data!C8 | B31: =Data!J8 | D31: =Data!L8 | E31: =F31*1000 | F31: =C31*1000/D31/650 | G31: =$C$3 | H31: =G31/F31 | I31: =H31/2 | J31: 1
A32: =Data!C9 | B32: =Data!J9 | D32: =Data!L9 | E32: =F32*1000 | F32: =C32*1000/D32/650 | G32: =$C$3 | H32: =G32/F32 | I32: =H32/2 | J32: 1
A33: =Data!C10 | B33: =Data!J10 | D33: =Data!L10 | E33: =F33*1000 | F33: =C33*1000/D33/650 | G33: =$C$3 | H33: =G33/F33 | I33: =H33/2 | J33: 1
A34: =Data!C11 | B34: =Data!J11 | D34: =Data!L11 | E34: =F34*1000 | F34: =C34*1000/D34/650 | G34: =$C$3 | H34: =G34/F34 | I34: =H34/2 | J34: 1
A35: =Data!C12 | B35: =Data!J12 | D35: =Data!L12 | E35: =F35*1000 | F35: =C35*1000/D35/650 | G35: =$C$3 | H35: =G35/F35 | I35: =H35/2 | J35: 1
A36: =Data!C13 | B36: =Data!J13 | D36: =Data!L13 | E36: =F36*1000 | F36: =C36*1000/D36/650 | G36: =$C$3 | H36: =G36/F36 | I36: =H36/2 | J36: 1
C38: Reagent volume (uL)
A39: =A9 | B39: =IF(M9=TRUE,"insert :","") | C39: =IF(M9=TRUE,I9,"") | D39: =IF($M39<>TRUE,"","backbone: ") | E39: =IF($M39<>TRUE,"",I25) | F39: =IF($M39<>TRUE,"","H2O: ") | G39: =IF($M39<>TRUE,"",$A$3/2-E39-L39) | H39: =IF($M39<>TRUE,"","2×HiFi: ") | I39: =IF($M39<>TRUE,"",$A$3/2) | J39: =IF($M39<>TRUE,"","→ 50°C, 60 min") | L39: =IF(A40=A39,C39+L40,C39) | M39: =AND(A39>0,A38<>A39)
A40: =A10 | B40: =IF(M10=TRUE,"insert :","") | C40: =IF(M10=TRUE,I10,"") | D40: =IF($M40<>TRUE,"","backbone: ") | E40: =IF($M40<>TRUE,"",I26) | F40: =IF($M40<>TRUE,"","H2O: ") | G40: =IF($M40<>TRUE,"",$A$3/2-E40-L40) | H40: =IF($M40<>TRUE,"","2×HiFi: ") | I40: =IF($M40<>TRUE,"",$A$3/2) | J40: =IF($M40<>TRUE,"","→ 50°C, 60 min") | L40: =IF(A41=A40,C40+L41,C40) | M40: =AND(A40>0,A39<>A40)
A41: =A11 | B41: =IF(M11=TRUE,"insert :","") | C41: =IF(M11=TRUE,I11,"") | D41: =IF($M41<>TRUE,"","backbone: ") | E41: =IF($M41<>TRUE,"",I27) | F41: =IF($M41<>TRUE,"","H2O: ") | G41: =IF($M41<>TRUE,"",$A$3/2-E41-L41) | H41: =IF($M41<>TRUE,"","2×HiFi: ") | I41: =IF($M41<>TRUE,"",$A$3/2) | J41: =IF($M41<>TRUE,"","→ 50°C, 60 min") | L41: =IF(A42=A41,C41+L42,C41) | M41: =AND(A41>0,A40<>A41)
A42: =A12 | B42: =IF(M12=TRUE,"insert :","") | C42: =IF(M12=TRUE,I12,"") | D42: =IF($M42<>TRUE,"","backbone: ") | E42: =IF($M42<>TRUE,"",I28) | F42: =IF($M42<>TRUE,"","H2O: ") | G42: =IF($M42<>TRUE,"",$A$3/2-E42-L42) | H42: =IF($M42<>TRUE,"","2×HiFi: ") | I42: =IF($M42<>TRUE,"",$A$3/2) | J42: =IF($M42<>TRUE,"","→ 50°C, 60 min") | L42: =IF(A43=A42,C42+L43,C42) | M42: =AND(A42>0,A41<>A42)
A43: =A13 | B43: =IF(M13=TRUE,"insert :","") | C43: =IF(M13=TRUE,I13,"") | D43: =IF($M43<>TRUE,"","backbone: ") | E43: =IF($M43<>TRUE,"",I29) | F43: =IF($M43<>TRUE,"","H2O: ") | G43: =IF($M43<>TRUE,"",$A$3/2-E43-L43) | H43: =IF($M43<>TRUE,"","2×HiFi: ") | I43: =IF($M43<>TRUE,"",$A$3/2) | J43: =IF($M43<>TRUE,"","→ 50°C, 60 min") | L43: =IF(A44=A43,C43+L44,C43) | M43: =AND(A43>0,A42<>A43)
A44: =A14 | B44: =IF(M14=TRUE,"insert :","") | C44: =IF(M14=TRUE,I14,"") | D44: =IF($M44<>TRUE,"","backbone: ") | E44: =IF($M44<>TRUE,"",I30) | F44: =IF($M44<>TRUE,"","H2O: ") | G44: =IF($M44<>TRUE,"",$A$3/2-E44-L44) | H44: =IF($M44<>TRUE,"","2×HiFi: ") | I44: =IF($M44<>TRUE,"",$A$3/2) | J44: =IF($M44<>TRUE,"","→ 50°C, 60 min") | L44: =IF(A45=A44,C44+L45,C44) | M44: =AND(A44>0,A43<>A44)
...

Sheet TF
A1: =TODAY() | C1: Cloning with HiFi assembly
A3: 3. Transformation
B5: Samples | C5: =COUNTA(Data!C2:C13) | D5: samples
B6: DH5α competent cells | C6: =C5*25 | D6: uL | E6: 25 uL/sample
B7: Recovery medium | C7: =C5*900 | D7: uL | E7: 900 uL/sample
B8: LB+Amp plate | C8: =ROUNDUP(C5/4,0) | D8: plates | E8: 4-section plates can be used
A10: □ | B10: Take the required number of DH5α competent cells out of the -80°C freezer
B11: Start thawing in your hand while carrying, then thaw completely at room temperature
A12: □ | B12: Dispense 25 uL of DH5α per tube and add 2 uL of the assembly mix after the reaction
A13: □ | B13: Mix well by vortexing for 1~10 sec
A14: □ | B14: 0~10 min on ice (optional)
B15: Add the following 2 steps if needed
A16: □ | B16: Heat shock: 42°C, 45~90 sec
A17: □ | B17: 1~5 min on ice (required in this case)
A18: □ | B18: Add 900 uL of recovery medium and incubate at 200 rpm, 37°C for 30~60 min
A19: □ | B19: Add ~100 uL to a pre-warmed plate and spread it unevenly on purpose
A20: □ | B20: 37°C, overnight
B21: If more than 2 days pass, run a program of 37°C, 24 hr → 4°C, hold
B24: Sample list
B25: Sub. No. | C25: Plasmid name | D25: Plate | E25: Colony | F25: Memo
A26: =IF(Data!C2="","","□") | B26: =IF(Data!C2="","",Data!C2) | C26: =IF(Data!C2="","",Data!G2) | D26: =IF(Data!C2="","",ROUNDUP((ROW()-25)/4,0)&"-"&MOD(ROW()-26,4)+1)
A27: =IF(Data!C3="","","□") | B27: =IF(Data!C3="","",Data!C3) | C27: =IF(Data!C3="","",Data!G3) | D27: =IF(Data!C3="","",ROUNDUP((ROW()-25)/4,0)&"-"&MOD(ROW()-26,4)+1)
A28: =IF(Data!C4="","","□") | B28: =IF(Data!C4="","",Data!C4) | C28: =IF(Data!C4="","",Data!G4) | D28: =IF(Data!C4="","",ROUNDUP((ROW()-25)/4,0)&"-"&MOD(ROW()-26,4)+1)
A29: =IF(Data!C5="","","□") | B29: =IF(Data!C5="","",Data!C5) | C29: =IF(Data!C5="","",Data!G5) | D29: =IF(Data!C5="","",ROUNDUP((ROW()-25)/4,0)&"-"&MOD(ROW()-26,4)+1)
A30: =IF(Data!C6="","","□") | B30: =IF(Data!C6="","",Data!C6) | C30: =IF(Data!C6="","",Data!G6) | D30: =IF(Data!C6="","",ROUNDUP((ROW()-25)/4,0)&"-"&MOD(ROW()-26,4)+1)
A31: =IF(Data!C7="","","□") | B31: =IF(Data!C7="","",Data!C7) | C31: =IF(Data!C7="","",Data!G7) | D31: =IF(Data!C7="","",ROUNDUP((ROW()-25)/4,0)&"-"&MOD(ROW()-26,4)+1)
A32: =IF(Data!C8="","","□") | B32: =IF(Data!C8="","",Data!C8) | C32: =IF(Data!C8="","",Data!G8) | D32: =IF(Data!C8="","",ROUNDUP((ROW()-25)/4,0)&"-"&MOD(ROW()-26,4)+1)
A33: =IF(Data!C9="","","□") | B33: =IF(Data!C9="","",Data!C9) | C33: =IF(Data!C9="","",Data!G9) | D33: =IF(Data!C9="","",ROUNDUP((ROW()-25)/4,0)&"-"&MOD(ROW()-26,4)+1)
A34: =IF(Data!C10="","","□") | B34: =IF(Data!C10="","",Data!C10) | C34: =IF(Data!C10="","",Data!G10) | D34: =IF(Data!C10="","",ROUNDUP((ROW()-25)/4,0)&"-"&MOD(ROW()-26,4)+1)
A35: =IF(Data!C11="","","□") | B35: =IF(Data!C11="","",Data!C11) | C35: =IF(Data!C11="","",Data!G11) | D35: =IF(Data!C11="","",ROUNDUP((ROW()-25)/4,0)&"-"&MOD(ROW()-26,4)+1)
A36: =IF(Data!C12="","","□") | B36: =IF(Data!C12="","",Data!C12) | C36: =IF(Data!C12="","",Data!G12) | D36: =IF(Data!C12="","",ROUNDUP((ROW()-25)/4,0)&"-"&MOD(ROW()-26,4)+1)
A37: =IF(Data!C13="","","□") | B37: =IF(Data!C13="","",Data!C13) | C37: =IF(Data!C13="","",Data!G13) | D37: =IF(Data!C13="","",ROUNDUP((ROW()-25)/4,0)&"-"&MOD(ROW()-26,4)+1)
