Workbook

Sheet Data
A1: Plasmid Construction | B1: Project No. | C1: Sub. No. | D1: Method | E1: Plasmid map | F1: Length | G1: Plasmid name | H1: RE1 | I1: RE2 | J1: Backbone plasmid/gDNA | K1: Backbone prep. | L1: Length (bp) | M1: PCR primer/Oligo 1 | N1: PCR primer/Oligo 2 | O1: Template | P1: Length (bp) | Q1: PCR/Annealing | R1: DpnI | S1: Transformation | T1: Miniprep | U1: Plasmid Ext. | V1: Nanopore | W1: Sequence check | X1: Plasmid No. | Y1: Plasmid name | Z1: Competent cell | AA1: Conc | AB1: Design | AC1: Order | AD1: Obtained | AE1: Made by | AF1: Entered by | AG1: Project number

Sheet Anneal
A1: =TODAY() | C1: Cloning with Golden-gate assembly
A3: 1. 5' phosphorylation of oligo DNA
B4: Thaw the oligo DNA and T4 DNA Ligase Reaction Buffer at room temperature
B6: Samples | C6: =COUNTA(Data!C2:C49) | D6: samples
B7: Mix tubes to prepare | C7: =C6+2 | D7: tubes | E7: (samples + 2)
B9: • T4 PNK mix preparation
B10: Reagent | C10: Final | D10: 1 sample (uL) | E10: Mix (uL)
A11: □ | B11: milliQ | D11: 6.75 | E11: =D11*$C$7 | F11: uL
A12: □ | B12: T4 DNA Ligase Reaction Buffer | C12: 1x | D12: 1 | E12: =D12*$C$7 | F12: uL
A13: □ | B13: T4 Polynucleotide Kinase | C13: 5 units | D13: 0.25 | E13: =D13*$C$7 | F13: uL
B14: Total | D14: =SUM(D11:D13) | E14: =SUM(E11:E13) | F14: uL
B16: • Oligo mix preparation (one sample at a time)
B17: Reagent | C17: Final | D17: Volume (uL)
A18: □ | B18: T4PNK mix | D18: =$D$14 | F18: uL
A19: □ | B19: Oligo F | C19: 10 uM | D19: 1 | F19: uL
A20: □ | B20: Oligo R | C20: 10 uM | D20: 1 | F20: uL
B21: Total | D21: =SUM(D18:D20) | F21: uL
A23: □ | B23: Mix well by vortexing, then spin down
A24: □ | B24: Run the following reaction in a thermal cycler
B25: 37°C 30:00 → 95°C 10:00 → 95°C→85°C -2°C/sec → 85°C→25°C -0.3°C/sec
B26: (checkpoint) Can be stored at -30°C
B28: Oligo list
B29: Sub. No. | C29: Plasmid name | D29: Oligo F | E29: Oligo R
A30: =IF(Data!C2="","","□") | B30: =IF(Data!C2="","",Data!C2) | C30: =IF(Data!C2="","",Data!G2) | D30: =IF(Data!C2="","",Data!M2) | E30: =IF(Data!C2="","",Data!N2)
A31: =IF(Data!C3="","","□") | B31: =IF(Data!C3="","",Data!C3) | C31: =IF(Data!C3="","",Data!G3) | D31: =IF(Data!C3="","",Data!M3) | E31: =IF(Data!C3="","",Data!N3)
A32: =IF(Data!C4="","","□") | B32: =IF(Data!C4="","",Data!C4) | C32: =IF(Data!C4="","",Data!G4) | D32: =IF(Data!C4="","",Data!M4) | E32: =IF(Data!C4="","",Data!N4)
A33: =IF(Data!C5="","","□") | B33: =IF(Data!C5="","",Data!C5) | C33: =IF(Data!C5="","",Data!G5) | D33: =IF(Data!C5="","",Data!M5) | E33: =IF(Data!C5="","",Data!N5)
A34: =IF(Data!C6="","","□") | B34: =IF(Data!C6="","",Data!C6) | C34: =IF(Data!C6="","",Data!G6) | D34: =IF(Data!C6="","",Data!M6) | E34: =IF(Data!C6="","",Data!N6)
A35: =IF(Data!C7="","","□") | B35: =IF(Data!C7="","",Data!C7) | C35: =IF(Data!C7="","",Data!G7) | D35: =IF(Data!C7="","",Data!M7) | E35: =IF(Data!C7="","",Data!N7)
A36: =IF(Data!C8="","","□") | B36: =IF(Data!C8="","",Data!C8) | C36: =IF(Data!C8="","",Data!G8) | D36: =IF(Data!C8="","",Data!M8) | E36: =IF(Data!C8="","",Data!N8)
A37: =IF(Data!C9="","","□") | B37: =IF(Data!C9="","",Data!C9) | C37: =IF(Data!C9="","",Data!G9) | D37: =IF(Data!C9="","",Data!M9) | E37: =IF(Data!C9="","",Data!N9)
A38: =IF(Data!C10="","","□") | B38: =IF(Data!C10="","",Data!C10) | C38: =IF(Data!C10="","",Data!G10) | D38: =IF(Data!C10="","",Data!M10) | E38: =IF(Data!C10="","",Data!N10)
A39: =IF(Data!C11="","","□") | B39: =IF(Data!C11="","",Data!C11) | C39: =IF(Data!C11="","",Data!G11) | D39: =IF(Data!C11="","",Data!M11) | E39: =IF(Data!C11="","",Data!N11)
A40: =IF(Data!C12="","","□") | B40: =IF(Data!C12="","",Data!C12) | C40: =IF(Data!C12="","",Data!G12) | D40: =IF(Data!C12="","",Data!M12) | E40: =IF(Data!C12="","",Data!N12)
A41: =IF(Data!C13="","","□") | B41: =IF(Data!C13="","",Data!C13) | C41: =IF(Data!C13="","",Data!G13) | D41: =IF(Data!C13="","",Data!M13) | E41: =IF(Data!C13="","",Data!N13)
... A77: =IF(Data!C49="","","□") | B77: =IF(Data!C49="","",Data!C49) | C77: =IF(Data!C49="","",Data!G49) | D77: =IF(Data!C49="","",Data!M49) | E77: =IF(Data!C49="","",Data!N49)

Sheet GGA
A1: =TODAY() | C1: Cloning with Golden-gate assembly
A3: 2. Golden-gate assembly
A4: □ | B4: Thaw the oligo mix (stored at -30°C), the plasmid and T4 DNA Ligase Reaction Buffer at room temperature
A5: □ | B5: Dilute the oligo mix 200-fold with water (final 50 nM): 1 uL oligo mix + 199 uL milliQ
B6: For BsaI and BsmBI see 2-1; for the others see 2-2
B8: Samples | C8: =C9+C10 | D8: samples
B9: of which 2-1 (BsaI / BsmBI) | C9: =COUNTIF($F$44:$F$91,"2-1") | D9: samples
B10: of which 2-2 (others) | C10: =COUNTIF($F$44:$F$91,"2-2") | D10: samples
B11: Total volume per reaction | C11: 6 | D11: uL
B12: Backbone plasmid | C12: 0.4 | D12: uL/sample | E12: No concentration measurement needed (fixed value)
B14: • 2-1. BsaI ligation mix preparation (NEBridge® Golden Gate Enzyme Mix (BsaI-HFv2), E1601, NEB)
D15: Mix tubes | E15: =IF($C$9=0,0,$C$9+2) | F15: tubes (samples + 2)
B16: Reagent | C16: Final | D16: 1 sample (uL) | E16: Mix (uL) | F16: Notes
A17: □ | B17: milliQ | D17: =$C$11-D18-D19-D21-D22 | E17: =D17*$E$15
A18: □ | B18: T4 DNA Ligase Reaction Buffer | C18: 1x | D18: 0.6 | E18: =D18*$E$15
A19: □ | B19: NEBridge Golden Gate Enzyme Mix (BsaI-HFv2) | D19: 0.3 | E19: =D19*$E$15
B20: Master mix subtotal | D20: =SUM(D17:D19) | E20: =SUM(E17:E19)
A21: □ | B21: Backbone plasmid | C21: 0.05 pmol | D21: =$C$12 | F21: Add to each tube individually
A22: □ | B22: 50 nM Oligo mix | C22: 0.05 pmol | D22: 0.6 | F22: Add to each tube individually
B23: Total | D23: =D20+SUM(D21:D22) | F23: uL
B25: • 2-2. NEBridge® Ligase Master Mix preparation (M1100, NEB)
D26: Mix tubes | E26: =IF($C$10=0,0,$C$10+2) | F26: tubes (samples + 2)
B27: Reagent | C27: Final | D27: 1 sample (uL) | E27: Mix (uL) | F27: Notes
A28: □ | B28: milliQ | D28: =$C$11-D29-D30-D32-D33 | E28: =D28*$E$26
A29: □ | B29: NEBridge Ligase Master Mix | C29: 1x | D29: 2 | E29: =D29*$E$26
A30: □ | B30: Type IIS RE | D30: 0.4 | E30: =D30*$E$26 | F30: =IFERROR(INDEX($E$44:$E$91,MATCH("2-2",$F$44:$F$91,0)),"")
B31: Master mix subtotal | D31: =SUM(D28:D30) | E31: =SUM(E28:E30)
A32: □ | B32: Backbone plasmid | C32: 0.05 pmol | D32: =$C$12 | F32: Add to each tube individually
A33: □ | B33: 50 nM Oligo mix | C33: 0.05 pmol | D33: 0.4 | F33: Add to each tube individually
B34: Total | D34: =D31+SUM(D32:D33) | F34: uL
B35: For PaqCI, add 0.2 uL/sample of PaqCI activator
B36: =IF($C$10=0,"",IF(COUNTIFS($F$44:$F$91,"2-2",$E$44:$E$91,$F$30)=$C$10,"","Note: there are several Type IIS REs in 2-2. Split the mix for each enzyme."))
A38: □ | B38: Mix well by vortexing, then spin down
A39: □ | B39: Run the following reaction in a thermal cycler: 37°C 30:00 → 60°C 5:00
A40: □ | B40: Pre-warm the required number of LB+Amp plates (4-section plates can be used) | C40: =ROUNDUP($C$8/4,0) | D40: plates
B41: (checkpoint) Can be stored at -30°C
B42: Addition per sample
B43: Sub. No. | C43: Plasmid name | D43: Backbone plasmid | E43: Type IIS RE | F43: mix | G43: Oligo mix
A44: =IF(Data!C2="","","□") | B44: =IF(Data!C2="","",Data!C2) | C44: =IF(Data!C2="","",Data!G2) | D44: =IF(Data!C2="","",Data!J2) | E44: =IF(Data!C2="","",Data!H2) | F44: =IF(Data!C2="","",IF(OR(LEFT(Data!H2,4)="BsaI",LEFT(Data!H2,5)="BsmBI"),"2-1","2-2")) | G44: =IF(Data!C2="","",Data!M2&" / "&Data!N2)
A45: =IF(Data!C3="","","□") | B45: =IF(Data!C3="","",Data!C3) | C45: =IF(Data!C3="","",Data!G3) | D45: =IF(Data!C3="","",Data!J3) | E45: =IF(Data!C3="","",Data!H3) | F45: =IF(Data!C3="","",IF(OR(LEFT(Data!H3,4)="BsaI",LEFT(Data!H3,5)="BsmBI"),"2-1","2-2")) | G45: =IF(Data!C3="","",Data!M3&" / "&Data!N3)
...

Sheet TF
A1: =TODAY() | C1: Cloning with Golden-gate assembly
A3: 3. Transformation
B5: Samples | C5: =GGA!C8 | D5: samples
B6: DH5α competent cells | C6: =C5*25 | D6: uL | E6: 25 uL/sample
B7: Recovery medium | C7: =C5*900 | D7: uL | E7: 900 uL/sample
B8: LB+Amp plate | C8: =ROUNDUP(C5/4,0) | D8: plates | E8: 4-section plates can be used
A10: □ | B10: Take the required number of DH5α competent cells out of the -80°C freezer
B11: Start thawing in your hand while carrying, then thaw completely at room temperature
A12: □ | B12: Dispense 25 uL of DH5α per tube and add 2 uL of the ligation mix after the reaction
A13: □ | B13: Mix well by vortexing for 1~10 sec
A14: □ | B14: 0~10 min on ice (optional)
B15: Add the following 2 steps if needed
A16: □ | B16: Heat shock: 42°C, 45~90 sec
A17: □ | B17: 1~5 min on ice (required in this case)
A18: □ | B18: Add 900 uL of recovery medium and incubate at 200 rpm, 37°C for 30~60 min
A19: □ | B19: Add ~100 uL to a pre-warmed plate and spread it unevenly on purpose
A20: □ | B20: 37°C, overnight
B21: If more than 2 days pass, run a program of 37°C, 24 hr → 4°C, hold
B24: Sample list
B25: Sub. No. | C25: Plasmid name | D25: Plate | E25: Colony | F25: Memo
A26: =IF(Data!C2="","","□") | B26: =IF(Data!C2="","",Data!C2) | C26: =IF(Data!C2="","",Data!G2) | D26: =IF(Data!C2="","",ROUNDUP((ROW()-25)/4,0)&"-"&MOD(ROW()-26,4)+1)
A27: =IF(Data!C3="","","□") | B27: =IF(Data!C3="","",Data!C3) | C27: =IF(Data!C3="","",Data!G3) | D27: =IF(Data!C3="","",ROUNDUP((ROW()-25)/4,0)&"-"&MOD(ROW()-26,4)+1)
A28: =IF(Data!C4="","","□") | B28: =IF(Data!C4="","",Data!C4) | C28: =IF(Data!C4="","",Data!G4) | D28: =IF(Data!C4="","",ROUNDUP((ROW()-25)/4,0)&"-"&MOD(ROW()-26,4)+1)
A29: =IF(Data!C5="","","□") | B29: =IF(Data!C5="","",Data!C5) | C29: =IF(Data!C5="","",Data!G5) | D29: =IF(Data!C5="","",ROUNDUP((ROW()-25)/4,0)&"-"&MOD(ROW()-26,4)+1)
A30: =IF(Data!C6="","","□") | B30: =IF(Data!C6="","",Data!C6) | C30: =IF(Data!C6="","",Data!G6) | D30: =IF(Data!C6="","",ROUNDUP((ROW()-25)/4,0)&"-"&MOD(ROW()-26,4)+1)
A31: =IF(Data!C7="","","□") | B31: =IF(Data!C7="","",Data!C7) | C31: =IF(Data!C7="","",Data!G7) | D31: =IF(Data!C7="","",ROUNDUP((ROW()-25)/4,0)&"-"&MOD(ROW()-26,4)+1)
A32: =IF(Data!C8="","","□") | B32: =IF(Data!C8="","",Data!C8) | C32: =IF(Data!C8="","",Data!G8) | D32: =IF(Data!C8="","",ROUNDUP((ROW()-25)/4,0)&"-"&MOD(ROW()-26,4)+1)
A33: =IF(Data!C9="","","□") | B33: =IF(Data!C9="","",Data!C9) | C33: =IF(Data!C9="","",Data!G9) | D33: =IF(Data!C9="","",ROUNDUP((ROW()-25)/4,0)&"-"&MOD(ROW()-26,4)+1)
A34: =IF(Data!C10="","","□") | B34: =IF(Data!C10="","",Data!C10) | C34: =IF(Data!C10="","",Data!G10) | D34: =IF(Data!C10="","",ROUNDUP((ROW()-25)/4,0)&"-"&MOD(ROW()-26,4)+1)
A35: =IF(Data!C11="","","□") | B35: =IF(Data!C11="","",Data!C11) | C35: =IF(Data!C11="","",Data!G11) | D35: =IF(Data!C11="","",ROUNDUP((ROW()-25)/4,0)&"-"&MOD(ROW()-26,4)+1)
A36: =IF(Data!C12="","","□") | B36: =IF(Data!C12="","",Data!C12) | C36: =IF(Data!C12="","",Data!G12) | D36: =IF(Data!C12="","",ROUNDUP((ROW()-25)/4,0)&"-"&MOD(ROW()-26,4)+1)
A37: =IF(Data!C13="","","□") | B37: =IF(Data!C13="","",Data!C13) | C37: =IF(Data!C13="","",Data!G13) | D37: =IF(Data!C13="","",ROUNDUP((ROW()-25)/4,0)&"-"&MOD(ROW()-26,4)+1)
... A73: =IF(Data!C49="","","□") | B73: =IF(Data!C49="","",Data!C49) | C73: =IF(Data!C49="","",Data!G49) | D73: =IF(Data!C49="","",ROUNDUP((ROW()-25)/4,0)&"-"&MOD(ROW()-26,4)+1)
